<?xml version="1.0" encoding="UTF-8"?>
<!-- Generated by org.testng.reporters.JUnitReportReporter -->
<testsuite hostname="K548LTRV" failures="1" tests="5" name="runner.Testrunner" time="92.621" errors="0" timestamp="2024-04-17T11:30:47 IST" skipped="0">
  <testcase classname="runner.Testrunner" name="runScenario" time="19.367">
    <failure message="expected [Sign up successful.] but found [This user already exist.]" type="java.lang.AssertionError">
      <![CDATA[java.lang.AssertionError: expected [Sign up successful.] but found [This user already exist.]
at org.testng.Assert.fail(Assert.java:111)
at org.testng.Assert.failNotEquals(Assert.java:1578)
at org.testng.Assert.assertEqualsImpl(Assert.java:150)
at org.testng.Assert.assertEquals(Assert.java:132)
at org.testng.Assert.assertEquals(Assert.java:656)
at org.testng.Assert.assertEquals(Assert.java:666)
at stepdefinitions.DemoBlazeSignupandLoginstepDefinition.user_checks_message_is_displayed_as_alert(DemoBlazeSignupandLoginstepDefinition.java:53)
at âœ½.User checks is "Sign up successful." is displayed as alert(classpath:features//DemoBlazeSignupandLogin.feature:12)
]]>
    </failure>
  </testcase> <!-- runScenario -->
  <testcase classname="runner.Testrunner" name="runScenario" time="17.620"/>
  <testcase classname="runner.Testrunner" name="runScenario" time="18.196"/>
  <testcase classname="runner.Testrunner" name="runScenario" time="16.745"/>
  <testcase classname="runner.Testrunner" name="runScenario" time="20.693"/>
</testsuite> <!-- runner.Testrunner -->
